[0m12:47:52.565991 [debug] [MainThread]: Sending event: {'category': 'dbt', 'action': 'invocation', 'label': 'start', 'context': [<snowplow_tracker.self_describing_json.SelfDescribingJson object at 0x102d7d510>, <snowplow_tracker.self_describing_json.SelfDescribingJson object at 0x104adbd90>, <snowplow_tracker.self_describing_json.SelfDescribingJson object at 0x104adb8b0>]}


============================== 12:47:52.575071 | 25f41d9a-9487-4e0c-a641-aaa9c892d52d ==============================
[0m12:47:52.575071 [info ] [MainThread]: Running with dbt=1.7.8
[0m12:47:52.576220 [debug] [MainThread]: running dbt with arguments {'printer_width': '80', 'indirect_selection': 'eager', 'log_cache_events': 'False', 'write_json': 'True', 'partial_parse': 'True', 'cache_selected_only': 'False', 'warn_error': 'None', 'version_check': 'True', 'fail_fast': 'False', 'log_path': 'logs', 'profiles_dir': '/Users/negreteo/.dbt', 'debug': 'False', 'use_colors': 'True', 'use_experimental_parser': 'False', 'no_print': 'None', 'quiet': 'False', 'warn_error_options': 'WarnErrorOptions(include=[], exclude=[])', 'invocation_command': 'dbt init', 'static_parser': 'True', 'log_format': 'default', 'target_path': 'None', 'introspect': 'True', 'send_anonymous_usage_stats': 'True'}
[0m12:47:58.089001 [error] [MainThread]: Encountered an error:

[0m12:47:58.094422 [error] [MainThread]: Traceback (most recent call last):
  File "/usr/local/lib/python3.10/site-packages/dbt/cli/requires.py", line 91, in wrapper
    result, success = func(*args, **kwargs)
  File "/usr/local/lib/python3.10/site-packages/dbt/cli/requires.py", line 76, in wrapper
    return func(*args, **kwargs)
  File "/usr/local/lib/python3.10/site-packages/dbt/cli/main.py", line 515, in init
    results = task.run()
  File "/usr/local/lib/python3.10/site-packages/dbt/task/init.py", line 322, in run
    project_name = self.get_valid_project_name()
  File "/usr/local/lib/python3.10/site-packages/dbt/task/init.py", line 276, in get_valid_project_name
    name = click.prompt("Enter a name for your project (letters, digits, underscore)")
  File "/usr/local/lib/python3.10/site-packages/click/termui.py", line 164, in prompt
    value = prompt_func(prompt)
  File "/usr/local/lib/python3.10/site-packages/click/termui.py", line 147, in prompt_func
    raise Abort() from None
click.exceptions.Abort

[0m12:47:58.098066 [debug] [MainThread]: Resource report: {"command_name": "init", "command_wall_clock_time": 5.6532564, "process_user_time": 3.595848, "process_kernel_time": 0.581438, "process_mem_max_rss": "92930048", "command_success": false, "process_in_blocks": "0", "process_out_blocks": "0"}
[0m12:47:58.100119 [debug] [MainThread]: Command `dbt init` failed at 12:47:58.099789 after 5.66 seconds
[0m12:47:58.100970 [debug] [MainThread]: Sending event: {'category': 'dbt', 'action': 'invocation', 'label': 'end', 'context': [<snowplow_tracker.self_describing_json.SelfDescribingJson object at 0x102d7d510>, <snowplow_tracker.self_describing_json.SelfDescribingJson object at 0x104adb8b0>, <snowplow_tracker.self_describing_json.SelfDescribingJson object at 0x104adab30>]}
[0m12:47:58.101986 [debug] [MainThread]: Flushing usage events
[0m13:48:20.125552 [debug] [MainThread]: Sending event: {'category': 'dbt', 'action': 'invocation', 'label': 'start', 'context': [<snowplow_tracker.self_describing_json.SelfDescribingJson object at 0x10c9db0a0>, <snowplow_tracker.self_describing_json.SelfDescribingJson object at 0x10e733ee0>, <snowplow_tracker.self_describing_json.SelfDescribingJson object at 0x10e733a00>]}


============================== 13:48:20.133820 | 1d6602e4-3d46-4b9d-8ffb-064e1d193b44 ==============================
[0m13:48:20.133820 [info ] [MainThread]: Running with dbt=1.7.8
[0m13:48:20.134964 [debug] [MainThread]: running dbt with arguments {'printer_width': '80', 'indirect_selection': 'eager', 'write_json': 'True', 'log_cache_events': 'False', 'partial_parse': 'True', 'cache_selected_only': 'False', 'profiles_dir': '/Users/negreteo/.dbt', 'debug': 'False', 'version_check': 'True', 'log_path': 'logs', 'warn_error': 'None', 'fail_fast': 'False', 'use_colors': 'True', 'use_experimental_parser': 'False', 'no_print': 'None', 'quiet': 'False', 'log_format': 'default', 'introspect': 'True', 'warn_error_options': 'WarnErrorOptions(include=[], exclude=[])', 'static_parser': 'True', 'target_path': 'None', 'invocation_command': 'dbt deps', 'send_anonymous_usage_stats': 'True'}
[0m13:48:20.136965 [error] [MainThread]: Encountered an error:
Runtime Error
  No dbt_project.yml found at expected path /Users/negreteo/Projects/airflow-astro/dbt_project.yml
  Verify that each entry within packages.yml (and their transitive dependencies) contains a file named dbt_project.yml
  
[0m13:48:20.140540 [debug] [MainThread]: Resource report: {"command_name": "deps", "command_wall_clock_time": 0.13703251, "process_user_time": 3.614017, "process_kernel_time": 0.531592, "process_mem_max_rss": "92286976", "command_success": false, "process_in_blocks": "0", "process_out_blocks": "0"}
[0m13:48:20.141781 [debug] [MainThread]: Command `dbt deps` failed at 13:48:20.141497 after 0.14 seconds
[0m13:48:20.142669 [debug] [MainThread]: Sending event: {'category': 'dbt', 'action': 'invocation', 'label': 'end', 'context': [<snowplow_tracker.self_describing_json.SelfDescribingJson object at 0x10c9db0a0>, <snowplow_tracker.self_describing_json.SelfDescribingJson object at 0x10e733dc0>, <snowplow_tracker.self_describing_json.SelfDescribingJson object at 0x10e732ad0>]}
[0m13:48:20.163302 [debug] [MainThread]: Flushing usage events
[0m13:49:28.206786 [debug] [MainThread]: Sending event: {'category': 'dbt', 'action': 'invocation', 'label': 'start', 'context': [<snowplow_tracker.self_describing_json.SelfDescribingJson object at 0x105b0a530>, <snowplow_tracker.self_describing_json.SelfDescribingJson object at 0x107863df0>, <snowplow_tracker.self_describing_json.SelfDescribingJson object at 0x107863910>]}


============================== 13:49:28.215190 | f0abeb8a-3625-4a24-8aa0-e2ff4b702872 ==============================
[0m13:49:28.215190 [info ] [MainThread]: Running with dbt=1.7.8
[0m13:49:28.216345 [debug] [MainThread]: running dbt with arguments {'printer_width': '80', 'indirect_selection': 'eager', 'log_cache_events': 'False', 'write_json': 'True', 'partial_parse': 'True', 'cache_selected_only': 'False', 'warn_error': 'None', 'version_check': 'True', 'debug': 'False', 'log_path': 'logs', 'fail_fast': 'False', 'profiles_dir': '/Users/negreteo/.dbt', 'use_colors': 'True', 'use_experimental_parser': 'False', 'no_print': 'None', 'quiet': 'False', 'log_format': 'default', 'introspect': 'True', 'static_parser': 'True', 'warn_error_options': 'WarnErrorOptions(include=[], exclude=[])', 'target_path': 'None', 'invocation_command': 'dbt debug', 'send_anonymous_usage_stats': 'True'}
[0m13:49:28.217542 [info ] [MainThread]: dbt version: 1.7.8
[0m13:49:28.218329 [info ] [MainThread]: python version: 3.10.13
[0m13:49:28.219011 [info ] [MainThread]: python path: /usr/local/opt/python@3.10/bin/python3.10
[0m13:49:28.219639 [info ] [MainThread]: os info: macOS-14.3.1-x86_64-i386-64bit
[0m13:49:29.149645 [info ] [MainThread]: Using profiles dir at /Users/negreteo/.dbt
[0m13:49:29.150429 [info ] [MainThread]: Using profiles.yml file at /Users/negreteo/.dbt/profiles.yml
[0m13:49:29.151084 [info ] [MainThread]: Using dbt_project.yml file at /Users/negreteo/Projects/airflow-astro/dbt_project.yml
[0m13:49:29.152048 [error] [MainThread]: Encountered an error:
Internal Error
  Profile should not be None if loading profile completed
[0m13:49:29.155222 [debug] [MainThread]: Resource report: {"command_name": "debug", "command_wall_clock_time": 1.0545994, "process_user_time": 4.531987, "process_kernel_time": 0.820443, "process_mem_max_rss": "114495488", "command_success": false, "process_in_blocks": "0", "process_out_blocks": "0"}
[0m13:49:29.156272 [debug] [MainThread]: Command `dbt debug` failed at 13:49:29.156018 after 1.06 seconds
[0m13:49:29.156997 [debug] [MainThread]: Sending event: {'category': 'dbt', 'action': 'invocation', 'label': 'end', 'context': [<snowplow_tracker.self_describing_json.SelfDescribingJson object at 0x105b0a530>, <snowplow_tracker.self_describing_json.SelfDescribingJson object at 0x106e5beb0>, <snowplow_tracker.self_describing_json.SelfDescribingJson object at 0x10bd80c40>]}
[0m13:49:29.157739 [debug] [MainThread]: Flushing usage events
[0m13:51:46.606692 [debug] [MainThread]: Sending event: {'category': 'dbt', 'action': 'invocation', 'label': 'start', 'context': [<snowplow_tracker.self_describing_json.SelfDescribingJson object at 0x108103880>, <snowplow_tracker.self_describing_json.SelfDescribingJson object at 0x109e637f0>, <snowplow_tracker.self_describing_json.SelfDescribingJson object at 0x109e63310>]}


============================== 13:51:46.614765 | d6112a36-fce5-4721-aac6-a68b62c661c3 ==============================
[0m13:51:46.614765 [info ] [MainThread]: Running with dbt=1.7.8
[0m13:51:46.615871 [debug] [MainThread]: running dbt with arguments {'printer_width': '80', 'indirect_selection': 'eager', 'write_json': 'True', 'log_cache_events': 'False', 'partial_parse': 'True', 'cache_selected_only': 'False', 'warn_error': 'None', 'debug': 'False', 'version_check': 'True', 'log_path': 'logs', 'profiles_dir': '/Users/negreteo/.dbt', 'fail_fast': 'False', 'use_colors': 'True', 'use_experimental_parser': 'False', 'no_print': 'None', 'quiet': 'False', 'log_format': 'default', 'static_parser': 'True', 'invocation_command': 'dbt compile', 'introspect': 'True', 'target_path': 'None', 'warn_error_options': 'WarnErrorOptions(include=[], exclude=[])', 'send_anonymous_usage_stats': 'True'}
[0m13:51:46.617094 [error] [MainThread]: Encountered an error:
Runtime Error
  No dbt_project.yml found at expected path /Users/negreteo/Projects/airflow-astro/dbt_project.yml
  Verify that each entry within packages.yml (and their transitive dependencies) contains a file named dbt_project.yml
  
[0m13:51:46.619955 [debug] [MainThread]: Resource report: {"command_name": "compile", "command_wall_clock_time": 0.12434758, "process_user_time": 3.557581, "process_kernel_time": 0.491612, "process_mem_max_rss": "92712960", "command_success": false, "process_in_blocks": "0", "process_out_blocks": "0"}
[0m13:51:46.621192 [debug] [MainThread]: Command `dbt compile` failed at 13:51:46.620905 after 0.13 seconds
[0m13:51:46.622076 [debug] [MainThread]: Sending event: {'category': 'dbt', 'action': 'invocation', 'label': 'end', 'context': [<snowplow_tracker.self_describing_json.SelfDescribingJson object at 0x108103880>, <snowplow_tracker.self_describing_json.SelfDescribingJson object at 0x109e63b50>, <snowplow_tracker.self_describing_json.SelfDescribingJson object at 0x109e63310>]}
[0m13:51:46.622867 [debug] [MainThread]: Flushing usage events
